<?xml version="1.0" ?>
<!-- =================================================================================== -->
<!-- |    This document was autogenerated by xacro from turtlebot3_manipulation.urdf.xacro | -->
<!-- |    EDITING THIS FILE BY HAND IS NOT RECOMMENDED                                 | -->
<!-- =================================================================================== -->
<!-- TurtleBot3 Manipulation -->
<robot name="turtlebot3_manipulation">
  <material name="black">
    <color rgba="0.0 0.0 0.0 1.0"/>
  </material>
  <material name="blue">
    <color rgba="0.0 0.0 0.8 1.0"/>
  </material>
  <material name="brown">
    <color rgba="0.8706 0.8118 0.7647 1.0"/>
  </material>
  <material name="dark">
    <color rgba="0.3 0.3 0.3 1.0"/>
  </material>
  <material name="green">
    <color rgba="0.0 0.8 0.0 1.0"/>
  </material>
  <material name="grey">
    <color rgba="0.5 0.5 0.5 1.0"/>
  </material>
  <material name="light_black">
    <color rgba="0.4 0.4 0.4 1.0"/>
  </material>
  <material name="orange">
    <color rgba="1.0 0.4235 0.0392 1.0"/>
  </material>
  <material name="red">
    <color rgba="0.8 0.0 0.0 1.0"/>
  </material>
  <material name="white">
    <color rgba="1.0 1.0 1.0 1.0"/>
  </material>
  <link name="base_footprint"/>
  <joint name="base_joint" type="fixed">
    <parent link="base_footprint"/>
    <child link="base_link"/>
    <origin rpy="0 0 0" xyz="0 0 0.010"/>
  </joint>
  <link name="base_link">
    <visual>
      <origin rpy="0 0 0" xyz="-0.064 0 0.0"/>
      <geometry>
        <mesh filename="package://meshes/turtlebot3_waffle_pi/base.stl" scale="0.001 0.001 0.001"/>
      </geometry>
      <material name="light_black"/>
    </visual>
    <collision>
      <origin rpy="0 0 0" xyz="-0.064 0 0.047"/>
      <geometry>
        <box size="0.266 0.266 0.094"/>
      </geometry>
    </collision>
    <inertial>
      <origin rpy="0 0 0" xyz="0 0 0"/>
      <mass value="1.3729096e+00"/>
      <inertia ixx="8.7002718e-03" ixy="-4.7576583e-05" ixz="1.1160499e-04" iyy="8.6195418e-03" iyz="-3.5422299e-06" izz="1.4612727e-02"/>
    </inertial>
  </link>
  <joint name="wheel_left_joint" type="continuous">
    <parent link="base_link"/>
    <child link="wheel_left_link"/>
    <origin rpy="-1.57 0 0" xyz="0.0 0.144 0.023"/>
    <axis xyz="0 0 1"/>
  </joint>
  <link name="wheel_left_link">
    <visual>
      <origin rpy="1.57 0 0" xyz="0 0 0"/>
      <geometry>
        <mesh filename="package://meshes/turtlebot3_waffle_pi/left_tire.stl" scale="0.001 0.001 0.001"/>
      </geometry>
      <material name="dark"/>
    </visual>
    <collision>
      <origin rpy="0 0 0" xyz="0 0 0"/>
      <geometry>
        <cylinder length="0.018" radius="0.033"/>
      </geometry>
    </collision>
    <inertial>
      <origin xyz="0 0 0"/>
      <mass value="2.8498940e-02"/>
      <inertia ixx="1.1175580e-05" ixy="-4.2369783e-11" ixz="-5.9381719e-09" iyy="1.1192413e-05" iyz="-1.4400107e-11" izz="2.0712558e-05"/>
    </inertial>
  </link>
  <joint name="wheel_right_joint" type="continuous">
    <parent link="base_link"/>
    <child link="wheel_right_link"/>
    <origin rpy="-1.57 0 0" xyz="0.0 -0.144 0.023"/>
    <axis xyz="0 0 1"/>
  </joint>
  <link name="wheel_right_link">
    <visual>
      <origin rpy="1.57 0 0" xyz="0 0 0"/>
      <geometry>
        <mesh filename="package://meshes/turtlebot3_waffle_pi/right_tire.stl" scale="0.001 0.001 0.001"/>
      </geometry>
      <material name="dark"/>
    </visual>
    <collision>
      <origin rpy="0 0 0" xyz="0 0 0"/>
      <geometry>
        <cylinder length="0.018" radius="0.033"/>
      </geometry>
    </collision>
    <inertial>
      <origin xyz="0 0 0"/>
      <mass value="2.8498940e-02"/>
      <inertia ixx="1.1175580e-05" ixy="-4.2369783e-11" ixz="-5.9381719e-09" iyy="1.1192413e-05" iyz="-1.4400107e-11" izz="2.0712558e-05"/>
    </inertial>
  </link>
  <joint name="caster_back_right_joint" type="fixed">
    <parent link="base_link"/>
    <child link="caster_back_right_link"/>
    <origin rpy="-1.57 0 0" xyz="-0.177 -0.064 -0.004"/>
  </joint>
  <link name="caster_back_right_link">
    <collision>
      <origin rpy="0 0 0" xyz="0 0.001 0"/>
      <geometry>
        <box size="0.030 0.009 0.020"/>
      </geometry>
    </collision>
    <inertial>
      <origin xyz="0 0 0"/>
      <mass value="0.005"/>
      <inertia ixx="0.001" ixy="0.0" ixz="0.0" iyy="0.001" iyz="0.0" izz="0.001"/>
    </inertial>
  </link>
  <joint name="caster_back_left_joint" type="fixed">
    <parent link="base_link"/>
    <child link="caster_back_left_link"/>
    <origin rpy="-1.57 0 0" xyz="-0.177 0.064 -0.004"/>
  </joint>
  <link name="caster_back_left_link">
    <collision>
      <origin rpy="0 0 0" xyz="0 0.001 0"/>
      <geometry>
        <box size="0.030 0.009 0.020"/>
      </geometry>
    </collision>
    <inertial>
      <origin xyz="0 0 0"/>
      <mass value="0.005"/>
      <inertia ixx="0.001" ixy="0.0" ixz="0.0" iyy="0.001" iyz="0.0" izz="0.001"/>
    </inertial>
  </link>
  <joint name="imu_joint" type="fixed">
    <parent link="base_link"/>
    <child link="imu_link"/>
    <origin rpy="0 0 0" xyz="0.0 0 0.068"/>
  </joint>
  <link name="imu_link"/>
  <joint name="scan_joint" type="fixed">
    <parent link="base_link"/>
    <child link="base_scan"/>
    <origin rpy="0 0 0" xyz="-0.1 0 0.122"/>
  </joint>
  <link name="base_scan">
    <!-- <visual>
      <origin rpy="0 0 0" xyz="0 0 0.0"/>
      <geometry>
        <mesh filename="package://meshes/turtlebot3_waffle_pi/ladar.stl" scale="0.001 0.001 0.001"/>
      </geometry>
      <material name="dark"/>
    </visual>
    <collision>
      <origin rpy="0 0 0" xyz="0.015 0 -0.0065"/>
      <geometry>
        <cylinder length="0.0315" radius="0.055"/>
      </geometry>
    </collision>
    <inertial>
      <mass value="0.114"/>
      <origin xyz="0 0 0"/>
      <inertia ixx="0.001" ixy="0.0" ixz="0.0" iyy="0.001" iyz="0.0" izz="0.001"/>
    </inertial> -->
  </link>
  <joint name="camera_joint" type="fixed">
    <parent link="base_link"/>
    <child link="camera_link"/>
    <origin rpy="0 0 0" xyz="0.073 -0.011 0.084"/>
  </joint>
  <link name="camera_link">
    <collision>
      <origin rpy="0 0 0" xyz="0.005 0.011 0.013"/>
      <geometry>
        <box size="0.015 0.030 0.027"/>
      </geometry>
    </collision>
  </link>
  <joint name="camera_rgb_joint" type="fixed">
    <parent link="camera_link"/>
    <child link="camera_rgb_frame"/>
    <origin rpy="0 0 0" xyz="0.003 0.011 0.009"/>
  </joint>
  <link name="camera_rgb_frame"/>
  <joint name="camera_rgb_optical_joint" type="fixed">
    <parent link="camera_rgb_frame"/>
    <child link="camera_rgb_optical_frame"/>
    <origin rpy="-1.57 0 -1.57" xyz="0 0 0"/>
  </joint>
  <link name="camera_rgb_optical_frame"/>
  <!-- Used for fixing OpenManipulator-X on TurtleBot3 Waffle Pi -->
  <joint name="base_fixed" type="fixed">
    <parent link="base_link"/>
    <child link="link1"/>
    <origin rpy="0 0 0" xyz="0.0 0.0 0.091"/>
  </joint>
  <link name="link1">
    <visual>
      <origin rpy="0 0 0" xyz="0 0 0"/>
      <geometry>
        <mesh filename="package://meshes/open_manipulator_x/link1r.stl" scale="0.001 0.001 0.001"/>
      </geometry>
      <material name="grey"/>
    </visual>
    <collision>
      <origin rpy="0 0 0" xyz="0 0 0"/>
      <geometry>
        <box size="0.05 0.05 0.05"/>
      </geometry>
    </collision>
    <inertial>
      <origin xyz="3.0876154e-04 0.0000000e+00 -1.2176461e-04"/>
      <mass value="7.9119962e-02"/>
      <inertia ixx="1.2505234e-05" ixy="0.0" ixz="-1.7855208e-07" iyy="2.1898364e-05" iyz="0.0" izz="1.9267361e-05"/>
    </inertial>
  </link>
  <joint name="joint1" type="revolute">
    <parent link="link1"/>
    <child link="link2"/>
    <origin rpy="0 0 0" xyz="0.012 0.0 0.017"/>
    <axis xyz="0 0 1"/>
    <limit effort="1" lower="-2.827433388230814" upper="2.827433388230814" velocity="4.8"/>
    <dynamics damping="0.1"/>
  </joint>
  <link name="link2">
    <visual>
      <origin rpy="0 0 0" xyz="0 0 0.019"/>
      <geometry>
        <mesh filename="package://meshes/open_manipulator_x/link2r.stl" scale="0.001 0.001 0.001"/>
      </geometry>
      <material name="grey"/>
    </visual>
    <collision>
      <origin rpy="0 0 0" xyz="0 0 0.019"/>
      <geometry>
        <mesh filename="package://meshes/open_manipulator_x/link2r.stl" scale="0.001 0.001 0.001"/>
      </geometry>
    </collision>
    <inertial>
      <origin xyz="-3.0184870e-04 5.4043684e-04 0.047433463999999995"/>
      <mass value="9.8406837e-02"/>
      <inertia ixx="3.4543422e-05" ixy="-1.6031095e-08" ixz="-3.8375155e-07" iyy="3.2689329e-05" iyz="2.8511935e-08" izz="1.8850320e-05"/>
    </inertial>
  </link>
  <joint name="joint2" type="revolute">
    <parent link="link2"/>
    <child link="link3"/>
    <origin rpy="0 0 0" xyz="0.0 0.0 0.0595"/>
    <axis xyz="0 1 0"/>
    <limit effort="1" lower="-1.790707812546182" upper="1.5707963267948966" velocity="4.8"/>
    <dynamics damping="0.1"/>
  </joint>
  <link name="link3">
    <visual>
      <origin rpy="0 0 0" xyz="0 0 0"/>
      <geometry>
        <mesh filename="package://meshes/open_manipulator_x/link3r.stl" scale="0.001 0.001 0.001"/>
      </geometry>
      <material name="grey"/>
    </visual>
    <collision>
      <origin rpy="0 0 0" xyz="0 0 0"/>
      <geometry>
        <mesh filename="package://meshes/open_manipulator_x/link3r.stl" scale="0.001 0.001 0.001"/>
      </geometry>
    </collision>
    <inertial>
      <origin xyz="1.0308393e-02 3.7743363e-04 1.0170197e-01"/>
      <mass value="1.3850917e-01"/>
      <inertia ixx="3.3055381e-04" ixy="-9.7940978e-08" ixz="-3.8505711e-05" iyy="3.4290447e-04" iyz="-1.5717516e-06" izz="6.0346498e-05"/>
    </inertial>
  </link>
  <joint name="joint3" type="revolute">
    <parent link="link3"/>
    <child link="link4"/>
    <origin rpy="0 0 0" xyz="0.024 0 0.128"/>
    <axis xyz="0 1 0"/>
    <limit effort="1" lower="-0.9424777960769379" upper="1.382300767579509" velocity="4.8"/>
    <dynamics damping="0.1"/>
  </joint>
  <link name="link4">
    <visual>
      <origin rpy="0 0 0" xyz="0 0 0"/>
      <geometry>
        <mesh filename="package://meshes/open_manipulator_x/link4r.stl" scale="0.001 0.001 0.001"/>
      </geometry>
      <material name="grey"/>
    </visual>
    <collision>
      <origin rpy="0 0 0" xyz="0 0 0"/>
      <geometry>
        <mesh filename="package://meshes/open_manipulator_x/link4r.stl" scale="0.001 0.001 0.001"/>
      </geometry>
    </collision>
    <inertial>
      <origin xyz="9.0909590e-02 3.8929816e-04 2.2413279e-04"/>
      <mass value="1.3274562e-01"/>
      <inertia ixx="3.0654178e-05" ixy="-1.2764155e-06" ixz="-2.6874417e-07" iyy="2.4230292e-04" iyz="1.1559550e-08" izz="2.5155057e-04"/>
    </inertial>
  </link>
  <joint name="joint4" type="revolute">
    <parent link="link4"/>
    <child link="link5"/>
    <origin rpy="0 0 0" xyz="0.124 0.0 0.0"/>
    <axis xyz="0 1 0"/>
    <limit effort="1" lower="-1.790707812546182" upper="2.0420352248333655" velocity="4.8"/>
    <dynamics damping="0.1"/>
  </joint>
  <link name="link5">
    <visual>
      <origin rpy="0 0 0" xyz="0 0 0"/>
      <geometry>
        <mesh filename="package://meshes/open_manipulator_x/link5r.stl" scale="0.001 0.001 0.001"/>
      </geometry>
      <material name="grey"/>
    </visual>
    <collision>
      <origin rpy="0 0 0" xyz="0 0 0"/>
      <geometry>
        <mesh filename="package://meshes/open_manipulator_x/link5r.stl" scale="0.001 0.001 0.001"/>
      </geometry>
    </collision>
    <inertial>
      <origin xyz="4.4206755e-02 3.6839985e-07 8.9142216e-03"/>
      <mass value="1.4327573e-01"/>
      <inertia ixx="8.0870749e-05" ixy="0.0" ixz="-1.0157896e-06" iyy="7.5980465e-05" iyz="0.0" izz="9.3127351e-05"/>
    </inertial>
  </link>
  <joint name="gripper_left_joint" type="prismatic">
    <parent link="link5"/>
    <child link="gripper_left_link"/>
    <origin rpy="0 0 0" xyz="0.0817 0.021 0.0"/>
    <axis xyz="0 1 0"/>
    <limit effort="1" lower="-0.010" upper="0.019" velocity="4.8"/>
    <dynamics damping="0.1"/>
  </joint>
  <link name="gripper_left_link">
    <visual>
      <origin rpy="0 0 0" xyz="0 0 0"/>
      <geometry>
        <mesh filename="package://meshes/open_manipulator_x/gripper_left_palm.stl" scale="0.001 0.001 0.001"/>
      </geometry>
      <material name="grey"/>
    </visual>
    <collision>
      <origin rpy="0 0 0" xyz="0 0 0"/>
      <geometry>
        <mesh filename="package://meshes/open_manipulator_x/gripper_left_palm.stl" scale="0.001 0.001 0.001"/>
      </geometry>
    </collision>
    <inertial>
      <origin xyz="0 0 0"/>
      <mass value="1.0e-03"/>
      <inertia ixx="1.0e-06" ixy="0.0" ixz="0.0" iyy="1.0e-06" iyz="0.0" izz="1.0e-06"/>
    </inertial>
  </link>
  <joint name="gripper_right_joint_mimic" type="fixed">
    <parent link="link5"/>
    <child link="dummy_mimic_fix"/>
  </joint>
  <link name="dummy_mimic_fix"/>
  <joint name="gripper_right_joint" type="prismatic">
    <parent link="link5"/>
    <child link="gripper_right_link"/>
    <origin rpy="0 0 0" xyz="0.0817 -0.021 0"/>
    <axis xyz="0 -1 0"/>
    <limit effort="1" lower="-0.010" upper="0.019" velocity="4.8"/>
    <mimic joint="gripper_left_joint" multiplier="1"/>
    <dynamics damping="0.1"/>
  </joint>
  <link name="gripper_right_link">
    <visual>
      <origin rpy="0 0 0" xyz="0 0 0"/>
      <geometry>
        <mesh filename="package://meshes/open_manipulator_x/gripper_right_palm.stl" scale="0.001 0.001 0.001"/>
      </geometry>
      <material name="grey"/>
    </visual>
    <collision>
      <origin rpy="0 0 0" xyz="0 0 0"/>
      <geometry>
        <mesh filename="package://meshes/open_manipulator_x/gripper_right_palm.stl" scale="0.001 0.001 0.001"/>
      </geometry>
    </collision>
    <inertial>
      <origin xyz="0 0 0"/>
      <mass value="1.0e-03"/>
      <inertia ixx="1.0e-06" ixy="0.0" ixz="0.0" iyy="1.0e-06" iyz="0.0" izz="1.0e-06"/>
    </inertial>
  </link>
  <joint name="end_effector_joint" type="fixed">
    <parent link="link5"/>
    <child link="end_effector_link"/>
    <origin rpy="0 0 0" xyz="0.126 0.0 0.0"/>
  </joint>
  <link name="end_effector_link">
    <visual>
      <origin rpy="0 0 0" xyz="0 0 0"/>
      <geometry>
        <box size="0.01 0.01 0.01"/>
      </geometry>
      <material name="red"/>
    </visual>
  </link>
</robot>
